Fixes [#2581](/samuelcolvin/pydantic/issues/2581). Using constraints such as `gt` or `le`
no longer raises `ValueError` due to unenforced constraint.
